Workbook

Sheet Bitcoin 2024 Incomplete
A1: Date | B1: Price | C1: Open | D1: High | E1: Low | F1: Vol. | G1: Change %
A2: 45621 | B2: 98600.6 | C2: 97948.8 | D2: 98872.4 | E2: 96953.4 | F2: 81.30K | G2: 0.0068
A3: 45620 | B3: 97935.2 | C3: 97696.4 | D3: 98552.6 | E3: 95765.4 | F3: 77.04K | G3: 0.0024
A4: 45619 | B4: 97699 | C4: 98927.2 | D4: 98927.2 | E4: 97180.9 | F4: 72.17K | G4: -0.0124
A5: 45618 | B5: 98929.7 | C5: 98381.2 | D5: 99617.4 | E5: 97182.2 | F5: 132.23K | G5: 0.0056
A6: 45617 | B6: 98374.5 | C6: 94308.7 | D6: 98937.2 | E6: 94063.8 | F6: 179.07K | G6: 0.0432
A7: 45616 | B7: 94303.9 | C7: 92252.6 | D7: 94836.1 | E7: 91517.4 | F7: 121.46K | G7: 0.0224
A8: 45615 | B8: 92239.2 | C8: 90482.1 | D8: 93918.5 | E8: 90378.7 | F8: 146.04K | G8: 0.0195
A9: 45614 | B9: 90478.7 | C9: 89843.3 | D9: 92567.1 | E9: 89410.4 | F9: 150.47K | G9: 0.0072
A10: 45613 | B10: 89833.7 | C10: 90569.4 | D10: 91441.6 | E10: 88736.1 | F10: 81.24K | G10: -0.0078
A11: 45612 | B11: 90539.1 | C11: 91035.3 | D11: 91748.9 | E11: 90079 | F11: 79.82K | G11: -0.0056
A12: 45611 | B12: 91046.5 | C12: 87297.2 | D12: 91833.1 | E12: 87118.8 | F12: 158.19K | G12: 0.043
A13: 45610 | B13: 87294 | C13: 90424.8 | D13: 91726.7 | E13: 86740.2 | F13: 153.34K | G13: -0.0346
... A331: 45292 | B331: 44183.4 | C331: 42272.5 | D331: 44187 | E331: 42196.7 | F331: 36.30K | G331: 0.0452

Sheet Bitcoin_10 28 24-01 13 25
A1: Date | B1: Price | C1: Open | D1: High | E1: Low | F1: Vol. | G1: Change %
A2: 45670 | B2: 93045.5 | C2: 94540.5 | D2: 95906.9 | E2: 92931.9 | F2: 45.81K | G2: -0.0157
A3: 45669 | B3: 94533.6 | C3: 94598 | D3: 95383.2 | E3: 93736.6 | F3: 31.61K | G3: -0.0007
A4: 45668 | B4: 94596.7 | C4: 94724 | D4: 95009.4 | E4: 93847.8 | F4: 29.16K | G4: -0.0013
A5: 45667 | B5: 94724.1 | C5: 92540.5 | D5: 95760.6 | E5: 92310.6 | F5: 125.42K | G5: 0.0236
A6: 45666 | B6: 92539.8 | C6: 95066.6 | D6: 95323.1 | E6: 91241.9 | F6: 132.78K | G6: -0.0266
A7: 45665 | B7: 95066.6 | C7: 96938.2 | D7: 97266.4 | E7: 92716.6 | F7: 100.36K | G7: -0.0192
A8: 45664 | B8: 96929.8 | C8: 102247.9 | D8: 102678.2 | E8: 96201.3 | F8: 99.77K | G8: -0.052
A9: 45663 | B9: 102248.7 | C9: 98373.2 | D9: 102474.5 | E9: 97932.3 | F9: 86.73K | G9: 0.0397
A10: 45662 | B10: 98347.7 | C10: 98220.1 | D10: 98823.1 | E10: 97300 | F10: 31.34K | G10: 0.0013
A11: 45661 | B11: 98219.9 | C11: 98168.9 | D11: 98742.6 | E11: 97568.9 | F11: 36.56K | G11: 0.0005
A12: 45660 | B12: 98167.5 | C12: 96960.2 | D12: 98963.3 | E12: 96090.6 | F12: 61.62K | G12: 0.0125
A13: 45659 | B13: 96960 | C13: 94561.1 | D13: 97808 | E13: 94381.2 | F13: 76.13K | G13: 0.0254
... A79: 45593 | B79: 69954.1 | C79: 68011.9 | D79: 70203.4 | E79: 67610 | F79: 103.97K | G79: 0.0287

Sheet SP500
A1: observation_date | B1: SP500
A2: 45292
A3: 45293 | B3: 4742.83
A4: 45294 | B4: 4704.81
A5: 45295 | B5: 4688.68
A6: 45296 | B6: 4697.24
A7: 45299 | B7: 4763.54
A8: 45300 | B8: 4756.5
A9: 45301 | B9: 4783.45
A10: 45302 | B10: 4780.24
A11: 45303 | B11: 4783.83
A12: 45306
A13: 45307 | B13: 4765.98
A14: 45308 | B14: 4739.21
A15: 45309 | B15: 4780.94
A16: 45310 | B16: 4839.81
A17: 45313 | B17: 4850.43
A18: 45314 | B18: 4864.6
A19: 45315 | B19: 4868.55
A20: 45316 | B20: 4894.16
A21: 45317 | B21: 4890.97
A22: 45320 | B22: 4927.93
A23: 45321 | B23: 4924.97
A24: 45322 | B24: 4845.65
... A36: 45338 | B36: 5005.57
A37: 45341
A38: 45342 | B38: 4975.51
A39: 45343 | B39: 4981.8
A40: 45344 | B40: 5087.03
A41: 45345 | B41: 5088.8
A42: 45348 | B42: 5069.53
A43: 45349 | B43: 5078.18
A44: 45350 | B44: 5069.76
A45: 45351 | B45: 5096.27
A46: 45352 | B46: 5137.08
A47: 45355 | B47: 5130.95
A48: 45356 | B48: 5078.65
A49: 45357 | B49: 5104.76
... A65: 45379 | B65: 5254.35
A66: 45380
...

Sheet BTC 2024
A1: Date | B1: Price | C1: Open | D1: High | E1: Low | F1: Vol. | G1: Change %
A2: 45657 | B2: 93557.2 | C2: 92777.2 | D2: 96163.4 | E2: 92036.2 | F2: 74.85K | G2: 0.0084
A3: 45656 | B3: 92779.8 | C3: 93718.7 | D3: 94936.4 | E3: 91522.3 | F3: 112.43K | G3: -0.01
A4: 45655 | B4: 93716.3 | C4: 95282.6 | D4: 95315.4 | E4: 93026.7 | F4: 47.71K | G4: -0.0165
A5: 45654 | B5: 95284.5 | C5: 94274.9 | D5: 95684.3 | E5: 94124.7 | F5: 32.97K | G5: 0.0107
A6: 45653 | B6: 94275.9 | C6: 95776.4 | D6: 97243.3 | E6: 93472.8 | F6: 85.12K | G6: -0.0157
A7: 45652 | B7: 95777.7 | C7: 99389.4 | D7: 99922.5 | E7: 95193.3 | F7: 74.60K | G7: -0.0364
A8: 45651 | B8: 99391.3 | C8: 98661.9 | D8: 99514.1 | E8: 97651.9 | F8: 39.80K | G8: 0.0073
A9: 45650 | B9: 98668.1 | C9: 94852.8 | D9: 99446.6 | E9: 93566.2 | F9: 69.86K | G9: 0.0402
A10: 45649 | B10: 94852.1 | C10: 95184.8 | D10: 96517.8 | E10: 92543.2 | F10: 133.24K | G10: -0.0035
A11: 45648 | B11: 95183.8 | C11: 97281.6 | D11: 97422.2 | E11: 94265.2 | F11: 100.64K | G11: -0.0213
A12: 45647 | B12: 97253.3 | C12: 97799.1 | D12: 99531.9 | E12: 96478.6 | F12: 123.36K | G12: -0.0055
A13: 45646 | B13: 97795.7 | C13: 97468.3 | D13: 98178.2 | E13: 92301.9 | F13: 221.18K | G13: 0.0034
... A367: 45292 | B367: 44183.4 | C367: 42272.5 | D367: 44187 | E367: 42196.7 | F367: 36.30K | G367: 0.0452

Sheet BTC 2014_Close
A1: Date | B1: Price
A2: 45657 | B2: 93557.2
A3: 45656 | B3: 92779.8
A4: 45655 | B4: 93716.3
A5: 45654 | B5: 95284.5
A6: 45653 | B6: 94275.9
A7: 45652 | B7: 95777.7
A8: 45651 | B8: 99391.3
A9: 45650 | B9: 98668.1
A10: 45649 | B10: 94852.1
A11: 45648 | B11: 95183.8
A12: 45647 | B12: 97253.3
A13: 45646 | B13: 97795.7
... A367: 45292 | B367: 44183.4

Sheet SP500 2024
A1: Column1 | B1: Column2
A2: 45292
A3: 45293 | B3: 4742.83
A4: 45294 | B4: 4704.81
A5: 45295 | B5: 4688.68
A6: 45296 | B6: 4697.24
A7: 45299 | B7: 4763.54
A8: 45300 | B8: 4756.5
A9: 45301 | B9: 4783.45
A10: 45302 | B10: 4780.24
A11: 45303 | B11: 4783.83
A12: 45306
A13: 45307 | B13: 4765.98
A14: 45308 | B14: 4739.21
A15: 45309 | B15: 4780.94
A16: 45310 | B16: 4839.81
A17: 45313 | B17: 4850.43
A18: 45314 | B18: 4864.6
A19: 45315 | B19: 4868.55
A20: 45316 | B20: 4894.16
A21: 45317 | B21: 4890.97
A22: 45320 | B22: 4927.93
A23: 45321 | B23: 4924.97
A24: 45322 | B24: 4845.65
... A36: 45338 | B36: 5005.57
A37: 45341
A38: 45342 | B38: 4975.51
A39: 45343 | B39: 4981.8
A40: 45344 | B40: 5087.03
A41: 45345 | B41: 5088.8
A42: 45348 | B42: 5069.53
A43: 45349 | B43: 5078.18
A44: 45350 | B44: 5069.76
A45: 45351 | B45: 5096.27
A46: 45352 | B46: 5137.08
A47: 45355 | B47: 5130.95
A48: 45356 | B48: 5078.65
A49: 45357 | B49: 5104.76
... A65: 45379 | B65: 5254.35
A66: 45380
...

Sheet 2024_ClosesQ1
A1: Date | B1: Price | C1: SP500.1
A2: 45380 | B2: 69871.7 | C2: 5254.35 | E2: =LN(B2/B3) -> -0.012662843 | F2: =LN(C2/C3) -> 0 | H2: =_xlfn.STDEV.P(E2:E65)*SQRT(65) -> 0.30226623 | I2: =_xlfn.STDEV.P(F2:F65)*SQRT(65) -> 0.053843545
A3: 45379 | B3: 70762.1 | C3: 5254.35 | E3: =LN(B3/B4) -> 0.018825915 | F3: =LN(C3/C4) -> 0.0011158888
A4: 45378 | B4: 69442.4 | C4: 5248.49 | E4: =LN(B4/B5) -> -0.00798761 | F4: =LN(C4/C5) -> 0.0085935659
A5: 45377 | B5: 69999.3 | C5: 5203.58 | E5: =LN(B5/B6) -> 0.0015340485 | F5: =LN(C5/C6) -> -0.0028037482
A6: 45376 | B6: 69892 | C6: 5218.19 | E6: =LN(B6/B7) -> 0.091425302 | F6: =LN(C6/C7) -> -0.0030595956
A7: 45373 | B7: 63785.5 | C7: 5234.18 | E7: =LN(B7/B8) -> -0.026582264 | F7: =LN(C7/C8) -> -0.0014032464
A8: 45372 | B8: 65503.8 | C8: 5241.53 | E8: =LN(B8/B9) -> -0.035250182 | F8: =LN(C8/C9) -> 0.0032313725
A9: 45371 | B9: 67854 | C9: 5224.62 | E9: =LN(B9/B10) -> 0.089417826 | F9: =LN(C9/C10) -> 0.0088646978
A10: 45370 | B10: 62050 | C10: 5178.51 | E10: =LN(B10/B11) -> -0.085580189 | F10: =LN(C10/C11) -> 0.0056332831
A11: 45369 | B11: 67594.1 | C11: 5149.42 | E11: =LN(B11/B12) -> -0.027283613 | F11: =LN(C11/C12) -> 0.0062981689
A12: 45366 | B12: 69463.7 | C12: 5117.09 | E12: =LN(B12/B13) -> -0.02731847 | F12: =LN(C12/C13) -> -0.0065039961
A13: 45365 | B13: 71387.5 | C13: 5150.48 | E13: =LN(B13/B14) -> -0.023244464 | F13: =LN(C13/C14) -> -0.0028752059
A14: 45364 | B14: 73066.3 | C14: 5165.31 | E14: =LN(B14/B15) -> 0.022086669 | F14: =LN(C14/C15) -> -0.0019263916
... A65: 45293 | B65: 44943.7 | C65: 4742.83 | E65: =LN(B65/B66) -> 0.017061442 | F65: =LN(C65/C66) -> -0.0056745644
A66: 45292 | B66: 44183.4 | C66: 4769.82

Sheet 2024_ClosesQ2
A1: Date | B1: Price | C1: SP500.1
A2: 45471 | B2: 60403.3 | C2: 5460.48 | E2: =LN(B2/B3) -> -0.021001914 | F2: =LN(C2/C3) -> -0.0040919885 | H2: =_xlfn.STDEV.P(E2:E65)*SQRT(65) -> 0.23652893 | I2: =_xlfn.STDEV.P(F2:F65)*SQRT(65) -> 0.05248386
A3: 45470 | B3: 61685.3 | C3: 5482.87 | E3: =LN(B3/B4) -> 0.013643694 | F3: =LN(C3/C4) -> 0.00090687066
A4: 45469 | B4: 60849.4 | C4: 5477.9 | E4: =LN(B4/B5) -> -0.015653497 | F4: =LN(C4/C5) -> 0.0015711783
A5: 45468 | B5: 61809.4 | C5: 5469.3 | E5: =LN(B5/B6) -> 0.024844421 | F5: =LN(C5/C6) -> 0.0039259309
A6: 45467 | B6: 60292.7 | C6: 5447.87 | E6: =LN(B6/B7) -> -0.061677848 | F6: =LN(C6/C7) -> -0.0030698792
A7: 45464 | B7: 64128.5 | C7: 5464.62 | E7: =LN(B7/B8) -> -0.011254333 | F7: =LN(C7/C8) -> -0.0015633874
A8: 45463 | B8: 64854.3 | C8: 5473.17 | E8: =LN(B8/B9) -> -0.0019501651 | F8: =LN(C8/C9) -> 0
A9: 45462 | B9: 64980.9 | C9: 5473.17 | E9: =LN(B9/B10) -> -0.0027508685 | F9: =LN(C9/C10) -> -0.0025291523
A10: 45461 | B10: 65159.9 | C10: 5487.03 | E10: =LN(B10/B11) -> -0.020339653 | F10: =LN(C10/C11) -> 0.0025181898
A11: 45460 | B11: 66498.8 | C11: 5473.23 | E11: =LN(B11/B12) -> 0.0070020266 | F11: =LN(C11/C12) -> 0.0076351859
A12: 45457 | B12: 66034.8 | C12: 5431.6 | E12: =LN(B12/B13) -> -0.011118429 | F12: =LN(C12/C13) -> -0.00039391313
A13: 45456 | B13: 66773.1 | C13: 5433.74 | E13: =LN(B13/B14) -> -0.022025104 | F13: =LN(C13/C14) -> 0.0023418287
A14: 45455 | B14: 68260.1 | C14: 5421.03 | E14: =LN(B14/B15) -> 0.01387101 | F14: =LN(C14/C15) -> 0.0084677272
... A65: 45384 | B65: 65439.2 | C65: 5205.81 | E65: =LN(B65/B66) -> -0.06256796 | F65: =LN(C65/C66) -> -0.0072653957
A66: 45383 | B66: 69664.4 | C66: 5243.77

Sheet 2024_ClosesQ3
A1: Date | B1: Price | C1: SP500.1
A2: 45565 | B2: 63339.2 | C2: 5762.48 | E2: =LN(B2/B3) -> -0.03775518 | F2: =LN(C2/C3) -> 0.0042275934 | H2: =_xlfn.STDEV.P(E2:E65)*SQRT(65) -> 0.2927054 | I2: =_xlfn.STDEV.P(F2:F65)*SQRT(65) -> 0.081477478
A3: 45562 | B3: 65776.3 | C3: 5738.17 | E3: =LN(B3/B4) -> 0.009172891 | F3: =LN(C3/C4) -> -0.0012539689
A4: 45561 | B4: 65175.7 | C4: 5745.37 | E4: =LN(B4/B5) -> 0.031470927 | F4: =LN(C4/C5) -> 0.0040304808
A5: 45560 | B5: 63156.5 | C5: 5722.26 | E5: =LN(B5/B6) -> -0.017271782 | F5: =LN(C5/C6) -> -0.0018629116
A6: 45559 | B6: 64256.8 | C6: 5732.93 | E6: =LN(B6/B7) -> 0.014499982 | F6: =LN(C6/C7) -> 0.0025079697
A7: 45558 | B7: 63331.8 | C7: 5718.57 | E7: =LN(B7/B8) -> 0.0020642844 | F7: =LN(C7/C8) -> 0.0028053309
A8: 45555 | B8: 63201.2 | C8: 5702.55 | E8: =LN(B8/B9) -> 0.0041636403 | F8: =LN(C8/C9) -> -0.0019428555
A9: 45554 | B9: 62938.6 | C9: 5713.64 | E9: =LN(B9/B10) -> 0.018942603 | F9: =LN(C9/C10) -> 0.016834291
A10: 45553 | B10: 61757.6 | C10: 5618.26 | E10: =LN(B10/B11) -> 0.02373404 | F10: =LN(C10/C11) -> -0.0029006031
A11: 45552 | B11: 60309.1 | C11: 5634.58 | E11: =LN(B11/B12) -> 0.035372589 | F11: =LN(C11/C12) -> 0.00026447349
A12: 45551 | B12: 58213.1 | C12: 5633.09 | E12: =LN(B12/B13) -> -0.038724667 | F12: =LN(C12/C13) -> 0.0012558721
A13: 45548 | B13: 60511.6 | C13: 5626.02 | E13: =LN(B13/B14) -> 0.040075791 | F13: =LN(C13/C14) -> 0.0053930969
A14: 45547 | B14: 58134.5 | C14: 5595.76 | E14: =LN(B14/B15) -> 0.013783503 | F14: =LN(C14/C15) -> 0.0074673729
... A66: 45475 | B66: 62103.3 | C66: 5509.01 | E66: =LN(B66/B67) -> -0.012589631 | F66: =LN(C66/C67) -> 0.0061762198
A67: 45474 | B67: 62890.1 | C67: 5475.09

Sheet 2024_ClosesQ4
A1: Date | B1: Price | C1: SP500.1
A2: 45657 | B2: 93557.2 | C2: 5881.63 | E2: =LN(B2/B3) -> 0.0083440703 | F2: =LN(C2/C3) -> -0.0042939965 | H2: =_xlfn.STDEV.P(E2:E65)*SQRT(65) -> 0.26239775 | I2: =_xlfn.STDEV.P(F2:F65)*SQRT(65) -> 0.062809946
A3: 45656 | B3: 92779.8 | C3: 5906.94 | E3: =LN(B3/B4) -> -0.015996646 | F3: =LN(C3/C4) -> -0.01075969
A4: 45653 | B4: 94275.9 | C4: 5970.84 | E4: =LN(B4/B5) -> -0.015804292 | F4: =LN(C4/C5) -> -0.011117305
A5: 45652 | B5: 95777.7 | C5: 6037.59 | E5: =LN(B5/B6) -> -0.037034703 | F5: =LN(C5/C6) -> -0.00040570874
A6: 45651 | B6: 99391.3 | C6: 6040.04 | E6: =LN(B6/B7) -> 0.0073028921 | F6: =LN(C6/C7) -> 0
A7: 45650 | B7: 98668.1 | C7: 6040.04 | E7: =LN(B7/B8) -> 0.039442856 | F7: =LN(C7/C8) -> 0.010982197
A8: 45649 | B8: 94852.1 | C8: 5974.07 | E8: =LN(B8/B9) -> -0.030561772 | F8: =LN(C8/C9) -> 0.0072608955
A9: 45646 | B9: 97795.7 | C9: 5930.85 | E9: =LN(B9/B10) -> 0.0033759836 | F9: =LN(C9/C10) -> 0.010810476
A10: 45645 | B10: 97466.1 | C10: 5867.08 | E10: =LN(B10/B11) -> -0.027641607 | F10: =LN(C10/C11) -> -0.00086547346
A11: 45644 | B11: 100197.8 | C11: 5872.16 | E11: =LN(B11/B12) -> -0.057602381 | F11: =LN(C11/C12) -> -0.029936555
A12: 45643 | B12: 106138.9 | C12: 6050.61 | E12: =LN(B12/B13) -> 0.00076627092 | F12: =LN(C12/C13) -> -0.003871444
A13: 45642 | B13: 106057.6 | C13: 6074.08 | E13: =LN(B13/B14) -> 0.044650902 | F13: =LN(C13/C14) -> 0.0037921163
A14: 45639 | B14: 101426.2 | C14: 6051.09 | E14: =LN(B14/B15) -> 0.014062259 | F14: =LN(C14/C15) -> -2.6441168e-05
... A66: 45567 | B66: 60645.7 | C66: 5709.54 | E66: =LN(B66/B67) -> -0.0031247659 | F66: =LN(C66/C67) -> 0.00013837449
A67: 45566 | B67: 60835.5 | C67: 5708.75

Sheet 2024_Coses
A1: Date | B1: BTC | C1: SP500 | E1: Date | F1: BTC % | G1: SP500 % | I1: Date | J1: BTC ABS | K1: SP500 ABS
A2: 45657 | B2: 93557.2 | C2: 5881.63 | E2: 45657 | F2: =LN(Closes[[#This Row],[BTC]]/B3) -> 0.0083440703 | G2: =LN(Closes[[#This Row],[SP500]]/C3) -> -0.0042939965 | I2: 45657 | J2: =ABS(Percentages[[#This Row],[BTC %]]) -> 0.0083440703 | K2: =ABS(Percentages[[#This Row],[SP500 %]]) -> 0.0042939965 | L2: =SLOPE(F2:F262,G2:G262) -> -0.10044566
A3: 45656 | B3: 92779.8 | C3: 5906.94 | E3: 45656 | F3: =LN(Closes[[#This Row],[BTC]]/B4) -> -0.015996646 | G3: =LN(Closes[[#This Row],[SP500]]/C4) -> -0.01075969 | I3: 45656 | J3: =ABS(Percentages[[#This Row],[BTC %]]) -> 0.015996646 | K3: =ABS(Percentages[[#This Row],[SP500 %]]) -> 0.01075969
A4: 45653 | B4: 94275.9 | C4: 5970.84 | E4: 45653 | F4: =LN(Closes[[#This Row],[BTC]]/B5) -> -0.015804292 | G4: =LN(Closes[[#This Row],[SP500]]/C5) -> -0.011117305 | I4: 45653 | J4: =ABS(Percentages[[#This Row],[BTC %]]) -> 0.015804292 | K4: =ABS(Percentages[[#This Row],[SP500 %]]) -> 0.011117305
A5: 45652 | B5: 95777.7 | C5: 6037.59 | E5: 45652 | F5: =LN(Closes[[#This Row],[BTC]]/B6) -> -0.037034703 | G5: =LN(Closes[[#This Row],[SP500]]/C6) -> -0.00040570874 | I5: 45652 | J5: =ABS(Percentages[[#This Row],[BTC %]]) -> 0.037034703 | K5: =ABS(Percentages[[#This Row],[SP500 %]]) -> 0.00040570874
A6: 45651 | B6: 99391.3 | C6: 6040.04 | E6: 45651 | F6: =LN(Closes[[#This Row],[BTC]]/B7) -> 0.0073028921 | G6: =LN(Closes[[#This Row],[SP500]]/C7) -> 0 | I6: 45651 | J6: =ABS(Percentages[[#This Row],[BTC %]]) -> 0.0073028921 | K6: =ABS(Percentages[[#This Row],[SP500 %]]) -> 0
A7: 45650 | B7: 98668.1 | C7: 6040.04 | E7: 45650 | F7: =LN(Closes[[#This Row],[BTC]]/B8) -> 0.039442856 | G7: =LN(Closes[[#This Row],[SP500]]/C8) -> 0.010982197 | I7: 45650 | J7: =ABS(Percentages[[#This Row],[BTC %]]) -> 0.039442856 | K7: =ABS(Percentages[[#This Row],[SP500 %]]) -> 0.010982197
A8: 45649 | B8: 94852.1 | C8: 5974.07 | E8: 45649 | F8: =LN(Closes[[#This Row],[BTC]]/B9) -> -0.030561772 | G8: =LN(Closes[[#This Row],[SP500]]/C9) -> 0.0072608955 | I8: 45649 | J8: =ABS(Percentages[[#This Row],[BTC %]]) -> 0.030561772 | K8: =ABS(Percentages[[#This Row],[SP500 %]]) -> 0.0072608955
A9: 45646 | B9: 97795.7 | C9: 5930.85 | E9: 45646 | F9: =LN(Closes[[#This Row],[BTC]]/B10) -> 0.0033759836 | G9: =LN(Closes[[#This Row],[SP500]]/C10) -> 0.010810476 | I9: 45646 | J9: =ABS(Percentages[[#This Row],[BTC %]]) -> 0.0033759836 | K9: =ABS(Percentages[[#This Row],[SP500 %]]) -> 0.010810476
A10: 45645 | B10: 97466.1 | C10: 5867.08 | E10: 45645 | F10: =LN(Closes[[#This Row],[BTC]]/B11) -> -0.027641607 | G10: =LN(Closes[[#This Row],[SP500]]/C11) -> -0.00086547346 | I10: 45645 | J10: =ABS(Percentages[[#This Row],[BTC %]]) -> 0.027641607 | K10: =ABS(Percentages[[#This Row],[SP500 %]]) -> 0.00086547346
A11: 45644 | B11: 100197.8 | C11: 5872.16 | E11: 45644 | F11: =LN(Closes[[#This Row],[BTC]]/B12) -> -0.057602381 | G11: =LN(Closes[[#This Row],[SP500]]/C12) -> -0.029936555 | I11: 45644 | J11: =ABS(Percentages[[#This Row],[BTC %]]) -> 0.057602381 | K11: =ABS(Percentages[[#This Row],[SP500 %]]) -> 0.029936555
A12: 45643 | B12: 106138.9 | C12: 6050.61 | E12: 45643 | F12: =LN(Closes[[#This Row],[BTC]]/B13) -> 0.00076627092 | G12: =LN(Closes[[#This Row],[SP500]]/C13) -> -0.003871444 | I12: 45643 | J12: =ABS(Percentages[[#This Row],[BTC %]]) -> 0.00076627092 | K12: =ABS(Percentages[[#This Row],[SP500 %]]) -> 0.003871444
A13: 45642 | B13: 106057.6 | C13: 6074.08 | E13: 45642 | F13: =LN(Closes[[#This Row],[BTC]]/B14) -> 0.044650902 | G13: =LN(Closes[[#This Row],[SP500]]/C14) -> 0.0037921163 | I13: 45642 | J13: =ABS(Percentages[[#This Row],[BTC %]]) -> 0.044650902 | K13: =ABS(Percentages[[#This Row],[SP500 %]]) -> 0.0037921163
A14: 45639 | B14: 101426.2 | C14: 6051.09 | E14: 45639 | F14: =LN(Closes[[#This Row],[BTC]]/B15) -> 0.014062259 | G14: =LN(Closes[[#This Row],[SP500]]/C15) -> -2.6441168e-05 | I14: 45639 | J14: =ABS(Percentages[[#This Row],[BTC %]]) -> 0.014062259 | K14: =ABS(Percentages[[#This Row],[SP500 %]]) -> 2.6441168e-05
... A262: 45293 | B262: 44943.7 | C262: 4742.83 | E262: 45293 | F262: =LN(Closes[[#This Row],[BTC]]/B263) -> 0.017061442 | G262: =LN(Closes[[#This Row],[SP500]]/C263) -> -0.0056745644 | I262: 45293 | J262: =ABS(Percentages[[#This Row],[BTC %]]) -> 0.017061442 | K262: =ABS(Percentages[[#This Row],[SP500 %]]) -> 0.0056745644
A263: 45292 | B263: 44183.4 | C263: 4769.82 | E263: 45292 | I263: 45292

Sheet DATA
A1: 2024 | D1: Q1 | F1: Q2 | H1: Q3 | J1: Q4
B2: BTC | C2: SP500 | D2: BTC | E2: SP500 | F2: BTC | G2: SP500 | H2: BTC | I2: SP500 | J2: BTC | K2: SP500
A3: Price Change | B3: =('2024_Coses'!B2-'2024_Coses'!B263)/'2024_Coses'!B263 -> 1.117474 | C3: =('2024_Coses'!C2-'2024_Coses'!C263)/'2024_Coses'!C263 -> 0.23309265 | D3: =('2024_ClosesQ1'!B2-'2024_ClosesQ1'!B66)/'2024_ClosesQ1'!B66 -> 0.58140161 | E3: =('2024_ClosesQ1'!C2-'2024_ClosesQ1'!C66)/'2024_ClosesQ1'!C66 -> 0.10158245 | F3: =('2024_ClosesQ2'!B2-'2024_ClosesQ2'!B66)/'2024_ClosesQ2'!B66 -> -0.13293878 | G3: =('2024_ClosesQ2'!C2-'2024_ClosesQ2'!C66)/'2024_ClosesQ2'!C66 -> 0.041327137 | H3: =('2024_ClosesQ3'!B2-'2024_ClosesQ3'!B67)/'2024_ClosesQ3'!B67 -> 0.0071410286 | I3: =('2024_ClosesQ3'!C2-'2024_ClosesQ3'!C67)/'2024_ClosesQ3'!C67 -> 0.052490461 | J3: =('2024_ClosesQ4'!B2-'2024_ClosesQ4'!B67)/'2024_ClosesQ4'!B67 -> 0.5378718 | K3: =('2024_ClosesQ4'!C2-'2024_ClosesQ4'!C67)/'2024_ClosesQ4'!C67 -> 0.030283337
A4: High | B4: =MAX(Closes[BTC]) -> 106138.9 | C4: =MAX(Closes[SP500]) -> 6090.27 | D4: =MAX(_2024_ClosesQ1[Price]) -> 73066.3 | E4: =MAX(_2024_ClosesQ1[SP500.1]) -> 5254.35 | F4: =MAX(_2024_ClosesQ2[Price]) -> 71630.1 | G4: =MAX(_2024_ClosesQ2[SP500.1]) -> 5487.03 | H4: =MAX(_2024_ClosesQ3[Price]) -> 67908.6 | I4: =MAX(_2024_ClosesQ3[SP500.1]) -> 5762.48 | J4: =MAX(_2024_ClosesQ4[Price]) -> 106138.9 | K4: =MAX(_2024_ClosesQ4[SP500.1]) -> 6090.27
A5: Low | B5: =MIN(Closes[BTC]) -> 39556.4 | C5: =MIN(Closes[SP500]) -> 4688.68 | D5: =MIN(_2024_ClosesQ1[Price]) -> 39556.4 | E5: =MIN(_2024_ClosesQ1[SP500.1]) -> 4688.68 | F5: =MIN(_2024_ClosesQ2[Price]) -> 58331.2 | G5: =MIN(_2024_ClosesQ2[SP500.1]) -> 4967.23 | H5: =MIN(_2024_ClosesQ3[Price]) -> 53966.8 | I5: =MIN(_2024_ClosesQ3[SP500.1]) -> 5186.33 | J5: =MIN(_2024_ClosesQ4[Price]) -> 60316.2 | K5: =MIN(_2024_ClosesQ4[SP500.1]) -> 5695.94
A6: Volitility | B6: =_xlfn.STDEV.P('2024_Coses'!F2:F262)*SQRT(263) -> 1.1778037 | C6: =_xlfn.STDEV.P('2024_Coses'!G2:G262)*SQRT(263) -> 0.79863095 | D6: ='2024_ClosesQ1'!H2 -> 0.30226623 | E6: ='2024_ClosesQ1'!I2 -> 0.053843545 | F6: ='2024_ClosesQ2'!H2 -> 0.23652893 | G6: ='2024_ClosesQ2'!I2 -> 0.05248386 | H6: ='2024_ClosesQ3'!H2 -> 0.2927054 | I6: ='2024_ClosesQ3'!I2 -> 0.081477478 | J6: ='2024_ClosesQ4'!H2 -> 0.26239775 | K6: ='2024_ClosesQ4'!I2 -> 0.062809946
A9: Row Labels | B9: Average of BTC | C9: Average of SP500.1
A10: Jan | B10: 43071.826 | C10: 4802.0857
A11: Feb | B11: 50354.819 | C11: 5011.6571
A12: Mar | B12: 68086.181 | C12: 5174.5619
A13: Apr | B13: 66002.464 | C13: 5112.4927
A14: May | B14: 65323.752 | C14: 5252.5239
A15: Jun | B15: 65958.43 | C15: 5426.8035
A16: Jul | B16: 62667.504 | C16: 5541.0587
A17: Aug | B17: 59704.127 | C17: 5478.2145
A18: Sep | B18: 60326.786 | C18: 5614.2114
A19: Oct | B19: 65671.465 | C19: 5792.3196
A20: Nov | B20: 87067.052 | C20: 5933.1933
A21: Dec | B21: 98208.764 | C21: 6012.2327
A22: Grand Total | B22: 65926.46 | C22: 5427.9793

Sheet Query Elements
